Workbook

Sheet Instructions
A1: This is the file containing all the information about the Hydrogenation Process Case Study
A3: In Context_Input können die Devices, Phases und Molecules eingefügt werden, und dann kann man direkt deren Kontext beschreiben
A4: Daraufhin wird automatisch der kompakte Kontext in Context_Compact erstellt
A5: Diesen kann man dann rauskopieren in die Excel context_connections.xlsx
A6: Wenn man dann python create_context_connections.py aufruft, erstellt es einem automatisch die entsprechenden Connections mit den Properties, die dann in das RO-Crate eingefügt werden können
A7: Für das Einfügen habe ich bis jetzt noch keine Automatisierungsschritt erstellt.

Sheet Overview
A1: Case Study | B1: Device | C1: Phase | D1: Molecules/Species | E1: Atom
A2: Hydrogenation | B2: Reactor | C2: Liquid Phase | D2: Hydrogen | E2: C
B3: Stirrer | C3: Gas Phase | D3: cat(H) | E3: H
B4: Jacket | C4: (Dispersed Gas Phase) | D4: cat-H | E4: O
B5: Sparger | C5: Solid Phase | D5: cat(X) | E5: cat (Pt)
C6: Catalyst Phase | D6: RDY
D7: cat-RDY
D8: RYE
D9: cat-RYE
D10: RYA
D11: cat-RYA
D12: REA
D13: cat-REA
D14: RDEt
D15: cat-RDEt
D16: Water
D17: Isopropanol (IPA)
A19: zink oxide | B19: pump 1 | C19: liquid 1: ZnCl2+H2O | D19: ZnCl2
B20: pump 2 | C20: liquid 2: KOH+H2O | D20: H2o
B21: reactor | C21: gas: Air | D21: KOH
B22: collection vessel | C22: solid: ZnO | D22: O2
B23: mfc | D23: N2
B24: pressure sensors (pumps, reactor, maxbe vessel) | D24: ZnO
B25: temperature sensor
B26: balance/scale
B27: pipes
A33: Molecules/Species
A34: Name | B34: Structural Formula | C34: Description | D34: Molecules | E34: exact Instance in Ansgars thesis
A35: Hydrogen | B35: H2 | D35: H
A36: cat(H) | C36: Free catalyst spot where one Hydrogen atom can attach | D36: cat
A37: cat-H | C37: Catalyst spot with one hydrogen atom attached | D37: H
A38: cat(X) | C38: Free catalyst spot where every other molecule can attach | D38: cat
A39: RDY | C39: two triple bonds | D39: C, H
A40: cat-RDY | C40: RDY bound to catalyst | D40: C, H, cat
A41: RYE | C41: one triple, one double bond | D41: C, H
A42: cat-RYE | C42: RYE bound to catalyst | D42: C, H, cat
A43: RYA | C43: one triple, one single bond | D43: C, H
A44: cat-RYA | C44: RYA bound to catalyst | D44: C, H, cat
A45: REA | C45: one double, one single bond | D45: C, H
A46: cat-REA | C46: REA bound to catalyst | D46: C, H, cat
...

Sheet CaseStudy_Hydrogenation
A1: Case Study | B1: Thing | C1: hasInformation | D1: Information | E1: hasEnergy | F1: Energy | G1: hasTime | H1: Time | I1: hasSpace | J1: Space | K1: hasStructure | L1: Structure | M1: hasSubstance | N1: Substance
B3: reactor | C3: hasOperationMode | D3: fedbatch | E3: hasSetTemperatureProfile | F3: #ReactorTemperatureProfile | G3: hasSequenceOfSteps | H3: #SequenceOfSteps | I3: hasVolume | J3: 300 | K3: hasReactorForm | L3: cylinder | M3: isMadeOfMaterial | N3: #ReactorMaterial
C4: hasDigitalObjectID | D4: 1 | E4: hasSetPressureProfile | F4: #ReactorPressureProfile | I4: hasVolumeUnit | J4: ml | K4: hasAspectRatioHeightToDiameter | L4: 1.4
C5: lastServicedTime | D5: ddmmyy - hhmm | I5: hasHeight | J5: 0.5
C6: lastUsedTime | D6: ddmmyy - hhmm | I6: hasHeightUnit | J6: m
C7: lastUsedPurpose | D7: hydrogenation | I7: hasDiameter | J7: 0.3
C8: hasSensorList | D8: #ReactorSensorList | I8: hasDiameterUnit | J8: m
C9: hasCleaningProcedure | D9: #ReactorCleaningProcedure
B14: stirrer | C14: hasDigitalObjectID | D14: 2 | E14: hasRotaionalSpeed | F14: 50 rpm | G14: hasStirringStartTime | H14: ddmmyy - hhmm | I14: hasHeight | J14: 1 | K14: hasStirrerForm | L14: anchor | M14: isMadeOfMaterial | N14: #StirrerMaterial
E15: hasAcceleration | F15: 0.5 m/s2 | G15: hasStirringEndTime | H15: ddmmyy - hhmm | I15: hasHeightUnit | J15: m | K15: hasAspectRatioHeightToDiameter | L15: 1.4
C16: lastUsedPurpose | D16: hydrogenation | E16: hasPowerInput | F16: 500 W | G16: lastUsedTime | H16: ddmmyy - hhmm | I16: hasDiameter | J16: 0.2
C17: hasCleaningProcedure | D17: #StirrerCleaningProcedure | I17: hasDiameterUnit | J17: m
B23: sparger | C23: hasDigitalObjectID | D23: 3 | E23: hasVolumeFlowrate | F23: 100 | G23: hasSpargingStartTime | H23: ddmmyy - hhmm | I23: hasLength | J23: 0.7 | K23: hasSpargerForm | L23: L-shaped | M23: isMadeOfMaterial | N23: #SpargerMaterial
C24: lastUsedTime | D24: ddmmyy - hhmm | E24: hasVolumeFlowrateUnit | F24: sccm | G24: hasSpargingEndTime | H24: ddmmyy - hhmm | I24: hasLengthUnit | J24: m
C25: lastUsedPurpose | D25: hydrogenation | E25: hasSetPressureInletFlow | F25: 2 | I25: hasDiameter | J25: 6
C26: hasCleaningProcedure | D26: #SpargerCleaningProcedure | E26: hasSetPressureInletFlowUnit | F26: bar | I26: hasDiameterUnit | J26: mm
B30: jacket | C30: hasDigitalObjectID | D30: 4 | E30: hasSetJacketTemperature | F30: 15 | G30: lastCoolingFluidChange | H30: ddmmyy - hhmm | I30: hasLength | J30: 0.7 | K30: hasJacketForm | L30: hollow cylinder, 5 spiral wounds | M30: isMadeOfMaterial | N30: #JacketMaterial, #CoolingFluid
C31: lastUsedTime | D31: ddmmyy - hhmm | E31: hasSetJacketTemperatureUnit | F31: celsius | I31: hasLengthUnit | J31: m
C32: lastUsedPurpose | D32: hydrogenation | E32: hasSetJacketPressure | F32: 1 | I32: hasDiameter | J32: 6
E33: hasSetJacketPressureUnit | F33: bar | I33: hasDiameterUnit | J33: mm
B37: liquid phase | C37: hasHomogeneity | D37: heterogeneous | G37: preparationTime | H37: ddmmyy - hhmm | I37: hasVolume | J37: 0.3 | K37: hasForm | L37: cylinder | M37: ContinuousPhaseConsistsOf | N37: #Water, #Solvent
C38: hasContinousPhase | D38: liquid | G38: lastUsedTime | H38: none | I38: hasVolumeUnit | J38: m3 | K38: hasSurfaceAreaWithGasPhase | L38: 10 | M38: DispersedGasPhaseConsistsOf | N38: #H2
C39: hasDispersedPhase | D39: #DispersedPhaseGas, #DispersedPhaseSolid | G39: lastUsedDuration | H39: none | I39: amountAdded | J39: 20 | K39: hasAreaUnit | L39: cm2 | M39: DispersedSolidPhaseConsistsOf | N39: #RDY
C40: hasEntropy | I40: amountAddedUnit | J40: ml | K40: hasBubbleSizeDistributionGas | M40: hasWaterConcentration | N40: 3
C41: hasEntropyUnit | K41: hasParticleSizeDIstributionSolid | M41: hasSolventConcentration | N41: 4
C42: lastUsedPurpose | D42: none | M42: hasH2Concentration | N42: 5
M43: hasRDYConcentration | N43: 6
M44: hasXXUnit | N44: mol/l
B48: solid phase | C48: hasHomogeneity | D48: homogeneous | G48: preparationTime | H48: ddmmyy - hhmm | I48: particleSizeDistribution | J48: #ParticleSizeDistributionSolidPhase | K48: hasForm | L48: pellets | M48: consistsOf | N48: #RDY
C49: hasContinousPhase | D49: solid | G49: lastUsedTime | H49: none | I49: hasMass | J49: 15 | M49: hasRDYConcentration | N49: 100
C50: hasDispersedPhase | D50: none | G50: lastUsedDuration | H50: none | I50: hasMassUnit | J50: g | M50: hasRDYConcentrationUnit | N50: mol/g
C51: hasEntropy
C52: hasEntropyUnit
C53: lastUsedPurpose | D53: none
B56: catalyst phase | C56: hasHomogeneity | D56: homogeneous | G56: preparationTime | H56: ddmmyy - hhmm | I56: hasMass | J56: 5 | K56: hasForm | L56: non-woven Mesh | M56: consisteOf | N56: #Catalyst
C57: hasContinousPhase | D57: solid | G57: lastUsedTime | H57: ddmmyy - hhmm | I57: hasMassUnit | J57: g | K57: hasPhaseStructure | L57: crystallized | M57: hasCatalystConcentration | N57: 50
C58: hasDispersedPhase | D58: none | G58: lastUsedDuration | H58: 4 | I58: amountAdded | J58: 2 | M58: hasCatalystConcentrationUnit | N58: mol/g
C59: hasEntropy | G59: hasDurationUnit | H59: h | I59: amountAddedUnit | J59: g
C60: hasEntropyUnit
C61: lastUsedPurpose | D61: hydrogenation
...

Sheet Context_Input
A1: Entity | B1: Information | C1: Energy | D1: Time | E1: Space | F1: Structure | G1: Substance | H1: Device Library | I1: Notes | J1: Type
A3: Reactor | J3: Device
A4: #Reactor | B4: #DigitalObjectID_Reactor | C4: #TemperatureSensor_Energy | D4: #LastUsedTime_Reactor | H4: Reactor Material (Substance)
A5: #Reactor | B5: #LastUsedPurpose_Reactor_BeforeFirstUse | C5: #PressureSensor_Energy | D5: #LastServicedTime_Reactor | H5: Size, Dimensions (Space)
A6: #Reactor | B6: #OperatingMode_Reactor | C6: #SetPressureProfile_Reactor | D6: #ExperimentalProcedure | H6: Geometry (Structure)
A7: #Reactor | C7: #SetTemperatureProfile_Reactor | H7: Usage History (Information)
H8: Last Used Time (Time)
H9: Model, Manufacturer (Information)
A15: Vessel | J15: Device
A16: #Vessel | B16: #DigitalObjectID_Vessel | C16: #Reactor_Energy | D16: #LastUsedTime_Vessel | H16: Vessel Material (Substance)
A17: #Vessel | B17: #LastUsedPurpose_Vessel_BeforeFirstUse | D17: #Reactor_Time | H17: Size, Dimensions (Space)
H18: Geometry (Structure)
H19: Usage History (Information)
H20: Last Used Time (Time)
A28: Stirrer | J28: Device
A29: #Stirrer | B29: #DigitalObjectID_Stirrer | C29: #Reactor_Energy | D29: #LastUsedTime_Stirrer | H29: Stirrer Material (Substance)
A30: #Stirrer | B30: #LastUsedPurpose_Stirrer_BeforeFirstUse | C30: #SetRPMProfile_Reactor | D30: #Reactor_Time | H30: Size, Dimensions (Space)
H31: Geometry (Structure)
H32: Usage History (Information)
H33: Last Used Time (Time)
H34: Stirrer Acceleration (Energy)
H35: Power Input (Energy)
A41: Sparger | J41: Device
A42: #Sparger | B42: #DigitalObjectID_Sparger | C42: #Reactor_Energy | D42: #LastUsedTime_Sparger | H42: Sparger Material (Substance)
A43: #Sparger | B43: #LastUsedPurpose_Sparger_BeforeFirstUse | C43: #SetPressureProfile_Sparger | D43: #Reactor_Time | H43: Size, Dimensions (Space)
H44: Geometry (Structure)
H45: Usage History (Information)
H46: Last Used Time (Time)
A54: Jacket | J54: Device
A55: #Jacket | B55: #DigitalObjectID_Jacket | C55: #Reactor_Energy | D55: #LastUsedTime_Jacket | H55: Jacket Material (Substance)
A56: #Jacket | B56: #LastUsedPurpose_Jacket_BeforeFirstUse | C56: #SetFlowrateProfile_Jacket | D56: #Reactor_Time | H56: Size, Dimensions (Space)
H57: Geometry (Structure)
H58: Usage History (Information)
H59: Last Used Time (Time)
A67: Temperature Sensor | J67: Device
A68: #TemperatureSensor | B68: #LastUsedPurpose_TemperatureSensor_BeforeFirstUse | C68: #Reactor_Energy | D68: #Reactor_Time | H68: TemperatureSensor Material (Substance)
A69: #TemperatureSensor | B69: #DigitalObjectID_TemperatureSensor | C69: #RecordedTemperature_Reactor | D69: #LastUsedTime_TemperatureSensor | H69: Size, Dimensions (Space)
H70: Geometry (Structure)
H71: Usage History (Information)
H72: Last Used Time (Time)
...

Sheet Context_Compact
A1: Entity | B1: Information | C1: Energy | D1: Time | E1: Space | F1: Structure | G1: Substance
A2: {=Context_Input!A4:G13} -> #Reactor | B2: #DigitalObjectID_Reactor | C2: #TemperatureSensor_Energy | D2: #LastUsedTime_Reactor | E2: 0 | F2: 0 | G2: 0
A3: #Reactor | B3: #LastUsedPurpose_Reactor_BeforeFirstUse | C3: #PressureSensor_Energy | D3: #LastServicedTime_Reactor | E3: 0 | F3: 0 | G3: 0
A4: #Reactor | B4: #OperatingMode_Reactor | C4: #SetPressureProfile_Reactor | D4: #ExperimentalProcedure | E4: 0 | F4: 0 | G4: 0
A5: #Reactor | B5: 0 | C5: #SetTemperatureProfile_Reactor | D5: 0 | E5: 0 | F5: 0 | G5: 0
A6: 0 | B6: 0 | C6: 0 | D6: 0 | E6: 0 | F6: 0 | G6: 0
A7: 0 | B7: 0 | C7: 0 | D7: 0 | E7: 0 | F7: 0 | G7: 0
A8: 0 | B8: 0 | C8: 0 | D8: 0 | E8: 0 | F8: 0 | G8: 0
A9: 0 | B9: 0 | C9: 0 | D9: 0 | E9: 0 | F9: 0 | G9: 0
A10: 0 | B10: 0 | C10: 0 | D10: 0 | E10: 0 | F10: 0 | G10: 0
A11: 0 | B11: 0 | C11: 0 | D11: 0 | E11: 0 | F11: 0 | G11: 0
A12: {=Context_Input!A16:G26} -> #Vessel | B12: #DigitalObjectID_Vessel | C12: #Reactor_Energy | D12: #LastUsedTime_Vessel | E12: 0 | F12: 0 | G12: 0
A13: #Vessel | B13: #LastUsedPurpose_Vessel_BeforeFirstUse | C13: 0 | D13: #Reactor_Time | E13: 0 | F13: 0 | G13: 0
A14: 0 | B14: 0 | C14: 0 | D14: 0 | E14: 0 | F14: 0 | G14: 0
A15: 0 | B15: 0 | C15: 0 | D15: 0 | E15: 0 | F15: 0 | G15: 0
A16: 0 | B16: 0 | C16: 0 | D16: 0 | E16: 0 | F16: 0 | G16: 0
A17: 0 | B17: 0 | C17: 0 | D17: 0 | E17: 0 | F17: 0 | G17: 0
A18: 0 | B18: 0 | C18: 0 | D18: 0 | E18: 0 | F18: 0 | G18: 0
A19: 0 | B19: 0 | C19: 0 | D19: 0 | E19: 0 | F19: 0 | G19: 0
A20: 0 | B20: 0 | C20: 0 | D20: 0 | E20: 0 | F20: 0 | G20: 0
A21: 0 | B21: 0 | C21: 0 | D21: 0 | E21: 0 | F21: 0 | G21: 0
A22: 0 | B22: 0 | C22: 0 | D22: 0 | E22: 0 | F22: 0 | G22: 0
A23: {=Context_Input!A29:G39} -> #Stirrer | B23: #DigitalObjectID_Stirrer | C23: #Reactor_Energy | D23: #LastUsedTime_Stirrer | E23: 0 | F23: 0 | G23: 0
A24: #Stirrer | B24: #LastUsedPurpose_Stirrer_BeforeFirstUse | C24: #SetRPMProfile_Reactor | D24: #Reactor_Time | E24: 0 | F24: 0 | G24: 0
A25: 0 | B25: 0 | C25: 0 | D25: 0 | E25: 0 | F25: 0 | G25: 0
A26: 0 | B26: 0 | C26: 0 | D26: 0 | E26: 0 | F26: 0 | G26: 0
A27: 0 | B27: 0 | C27: 0 | D27: 0 | E27: 0 | F27: 0 | G27: 0
A28: 0 | B28: 0 | C28: 0 | D28: 0 | E28: 0 | F28: 0 | G28: 0
A29: 0 | B29: 0 | C29: 0 | D29: 0 | E29: 0 | F29: 0 | G29: 0
A30: 0 | B30: 0 | C30: 0 | D30: 0 | E30: 0 | F30: 0 | G30: 0
A31: 0 | B31: 0 | C31: 0 | D31: 0 | E31: 0 | F31: 0 | G31: 0
A32: 0 | B32: 0 | C32: 0 | D32: 0 | E32: 0 | F32: 0 | G32: 0
A33: 0 | B33: 0 | C33: 0 | D33: 0 | E33: 0 | F33: 0 | G33: 0
A34: {=Context_Input!A42:G52} -> #Sparger | B34: #DigitalObjectID_Sparger | C34: #Reactor_Energy | D34: #LastUsedTime_Sparger | E34: 0 | F34: 0 | G34: 0
A35: #Sparger | B35: #LastUsedPurpose_Sparger_BeforeFirstUse | C35: #SetPressureProfile_Sparger | D35: #Reactor_Time | E35: 0 | F35: 0 | G35: 0
A36: 0 | B36: 0 | C36: 0 | D36: 0 | E36: 0 | F36: 0 | G36: 0
A37: 0 | B37: 0 | C37: 0 | D37: 0 | E37: 0 | F37: 0 | G37: 0
A38: 0 | B38: 0 | C38: 0 | D38: 0 | E38: 0 | F38: 0 | G38: 0
A39: 0 | B39: 0 | C39: 0 | D39: 0 | E39: 0 | F39: 0 | G39: 0
A40: 0 | B40: 0 | C40: 0 | D40: 0 | E40: 0 | F40: 0 | G40: 0
...

Sheet Context Hydrogenation
A1: Entity | B1: describes Context | C1: of Entity | D1: übertragbar auf scpecific? | E1: notes
A2: Reaction1 | B2: MoleculeContext, Phase Context | K2: Allgemein
A4: MaterialVolume_Reactor | B4: Space, Structure | C4: LiquidPhase, SolidPhase | K4: Entity | L4: describesContext
L5: Molecule | M5: Phase | N5: Device | O5: Notes | Q5: Information
A6: VesselEnergy | B6: LiquidPhase_Energy | E6: auch für alle anderen phasen die in der vessel sind | K6: Reaction | L6: Time? | M6: Time? Substance | Q6: Energy
A7: LiquidPhaseEnergy | B7: Water_Energy | E7: auch für alle anderen Moleküle die in der Phase sind | K7: Participant | L7: x | M7: ? | Q7: Time
A8: LiquidPhaseEnergy | B8: Solvent_Energy | E8: Runterreichen in die Moleküle | K8: ReactionMechanism | L8: no | M8: no | N8: no | Q8: Space
A9: #FinalMass_Dimer | B9: Dimer1_Energy, Dimer2_Energy | K9: Stream | M9: Space, Structure? | Q9: Structure
A10: #FinalMass_RDEt | B10: RDEt_Energy | K10: MaterialVolume | M10: Space, Structure | Q10: Substance
A11: #FinalMass_RDY | B11: RDY_Energy | K11: Device Energy | M11: Energy
A12: #InitialMassFraction_Solvent_LiquidPhase | B12: LiquidPhase_Substance | K12: Phase
A13: #InitialMassFraction_Water_LiquidPhase | B13: LiquidPhase_Substance | K13: Molecule
A14: #InitialVolume_LiquidPhase | B14: LiquidPhase_Space | K14: Sensor | L14: no | M14: no | N14: no | O14: ist eher in der Variable
A15: #RecordedPressure_Reactor | B15: PressureSensor_Energy | E15: wird von dem sensor direkt aufgezeichnet, und von dem aus übertragen wir es dann an alle anderen betroffenen entities | K15: Task (Cleaning) | N15: Information | O15: auch in der Variable?
A16: #RecordedTemperature_Reactor | B16: Temperature_Sensor_Energy | K16: Task (Experimental Procedure)
A17: #SetFlowrateProfile_Jacket | B17: CoolingFluidPhase_Energy (indirect?), Jacket_Energy (direct?) | D17: Oder eigentlich MFC? Und der überträgt es dann an die CoolingFluidPhase über den Stream? | K17: Task (Measuring) | M17: Energy?
A18: #SetPressureProfile_Reactor | B18: reactor energy | E18: kommt drauf an ob wir das als gegeben sehen oder ein eigenes setting-device haben | K18: ScalarVariables | M18: Energy (Mass) | N18: Energy (Stirrer Acceleration)
A19: #SetPressureProfile_Sparger | B19: sparger energy | K19: ProfileVariables | N19: Energy (Temperatureprofile) | O19: Wenn es nur set ist eigentlich nicht, dann vll information? Oder man muss irgendwo kennzeichnen, wann das set profile auch das tatsächlich umgesetzte Profil ist, wie zb bei den RPM
A20: #SetRPMProfile_Reactor | B20: Stirrer_Energy | K20: SeriesVariables | M20: space (hydrogen sparger phase through gas volume) | N20: Energy (measured temp, pressure)
A21: #SetTemperatureProfile_Reactor | B21: CoolingFluidPhase_Energy (direct?), Jacket_Energy (indirect?), reactor energy (indirect) | D21: hochreichen über den Stream? Oder wir geben es dem Stream mit und der reicht es hoch/runter | K21: Molecule Energy | M21: Substance
A22: #StartMassRDY | B22: RDY_Energy | K22: Last used device time | L22: Time | M22: Time | N22: Time
A23: #StirrerAcceleration | E23: Ist eig nur als Teil des Profiles relevant, und das Profile beschreibt dann die Energy
A24: #UsedGasVolume_H2 | B24: Space: Gas Phase, dispersed gas phase, hydrogen sparger phase? | E24: eig mfm und dann wird weitergereicht
A25: PressureSensor_Energy | B25: Reactor_Energy | E25: Hochreichen des Sensors
A26: Reactor_Energy | B26: Vessel_Energy, Sparger_Energy, Stirrer_Energy, TemperatureSensor_Energy, PressureSensor_Energy | E26: Runterreichen im Reactor
A27: VesselEnergy | B27: LiquidPhase_Energy, SolidPhase_Energy, CatalystPhase_Energy, GasPhase_Energy, DispersedGasPhase_Energy | E27: Runterrreichen in die Phase
A28: StirrerEnergy | B28: Reactor_Energy | E28: Hochrreichen des Stirrers
A29: RDY Energy | B29: SolidPhase Substance
A30: LiquidPhase_Space | B30: Water Space, Solvent Space
A31: Reactor Operating Mode | B31: Reactor Information
E32: für alle devices
A33: Last Used Time | B33: device time | E33: für alle devices
A34: last used purpose | B34: device information | E34: für alle devices
A35: sparger energy | B35: hydrogen sparger phase energy
A36: experimental procedure | B36: reactor time/history
A37: reactor time | B37: time of all its parts | E37: kann ich das so verallgemeinern? Nicht alle devices sind zb in allen experimental procedures beteiligt oder?
A38: #DigitalObjectID_Jacket | B38: Jacket Information
A39: #DigitalObjectID_Reactor | B39: Reactor Information
A40: #DigitalObjectID_Sparger | B40: Sparger Information
A41: #DigitalObjectID_Stirrer | B41: Stirrer Information
...
